<?xml version="1.0" ?>
<!-- =================================================================================== -->
<!-- |    This document was autogenerated by xacro from mecabotX_description.xacro     | -->
<!-- |    EDITING THIS FILE BY HAND IS NOT RECOMMENDED                                 | -->
<!-- =================================================================================== -->
<robot name="wheeltec_robot">
  <!-- Base link -->
  <link name="base_link">
    <visual>
      <origin rpy="0 0 0" xyz=" 0 0 0.15"/>
      <geometry>
        <box size="0.554 0.500 0.1"/>
      </geometry>
      <material name="white">
        <color rgba="1 1 1 1"/>
      </material>
    </visual>
  </link>
  <link name="left_wheel_link">
    <visual>
      <origin rpy="0 0 0" xyz="0 0 0"/>
      <geometry>
        <cylinder length="0.04" radius="0.1"/>
      </geometry>
      <material name="black">
        <color rgba="0 0 0 1"/>
      </material>
    </visual>
  </link>
  <joint name="left_wheel_link_joint" type="continuous">
    <origin rpy="1.57 0 0" xyz="-0.201 0.295 0.1"/>
    <parent link="base_link"/>
    <child link="left_wheel_link"/>
    <axis xyz="0 1 0"/>
  </joint>
  <link name="right_wheel_link">
    <visual>
      <origin rpy="0 0 0" xyz="0 0 0"/>
      <geometry>
        <cylinder length="0.04" radius="0.1"/>
      </geometry>
      <material name="black">
        <color rgba="0 0 0 1"/>
      </material>
    </visual>
  </link>
  <joint name="right_wheel_link_joint" type="continuous">
    <origin rpy="1.57 0 0" xyz="-0.201 -0.295 0.1"/>
    <parent link="base_link"/>
    <child link="right_wheel_link"/>
    <axis xyz="0 1 0"/>
  </joint>
  <link name="left_front_link">
    <visual>
      <origin rpy="0 0 0" xyz="0 0 0"/>
      <geometry>
        <cylinder length="0.04" radius="0.1"/>
      </geometry>
      <material name="black">
        <color rgba="0 0 0 1"/>
      </material>
    </visual>
  </link>
  <joint name="left_front_link_joint" type="continuous">
    <origin rpy="1.57 0 0" xyz="0.201 0.295 0.1"/>
    <parent link="base_link"/>
    <child link="left_front_link"/>
    <axis xyz="0 1 0"/>
  </joint>
  <link name="right_front_link">
    <visual>
      <origin rpy="0 0 0" xyz="0 0 0"/>
      <geometry>
        <cylinder length="0.04" radius="0.1"/>
      </geometry>
      <material name="black">
        <color rgba="0 0 0 1"/>
      </material>
    </visual>
  </link>
  <joint name="right_front_link_joint" type="continuous">
    <origin rpy="1.57 0 0" xyz="0.201 -0.295 0.1"/>
    <parent link="base_link"/>
    <child link="right_front_link"/>
    <axis xyz="0 1 0"/>
  </joint>
</robot>
